<?xml version="1.0"?>
<robot name="bot_xiaoche" xmlns:xacro="http://www.ros.org/wiki/xacro">

    <!-- 定义颜色 -->
    <material name="red">
        <color rgba="1 0 0 1"/> <!-- 红色 用于车身 -->
    </material>
    <material name="black">
        <color rgba="0 0 0 1"/> <!-- 黑色 用于车轮 -->
    </material>

    <!-- 定义车身 -->
    <link name="base_link">
        <visual>
            <geometry>
                <box size="0.5 0.3 0.2"/> <!-- 车身的长宽高 -->
            </geometry>
            <origin xyz="0 0 0" rpy="0 0 0"/> <!-- 车身的初始位置和姿态 -->
            <material name="red"/> <!-- 引用红色材质 -->
        </visual>
        <collision>
            <geometry>
                <box size="0.5 0.3 0.2"/> <!-- 车身的碰撞体积 -->
            </geometry>
            <origin xyz="0 0 0" rpy="0 0 0"/> <!-- 碰撞体积的初始位置和姿态 -->
        </collision>
        <inertial>
            <mass value="50.0"/> <!-- 车身的质量 -->
            <origin xyz="0 0 0" rpy="0 0 0"/> <!-- 质心的位置 -->
            <inertia ixx="1.0" ixy="0.0" ixz="0.0" iyy="1.0" iyz="0.0" izz="1.0"/> <!-- 惯性矩阵 -->
        </inertial>
    </link>

    <!-- 定义车轮 -->
    <xacro:macro name="wheel" params="name x y z">
        <link name="${name}">
            <visual>
                <geometry>
                    <cylinder radius="0.1" length="0.05"/> <!-- 轮子的半径和厚度 -->
                </geometry>
                <origin xyz="0 0 -0.0667" rpy="1.5707963 0 0"/> <!-- 轮子的初始位置和姿态 -->
                <material name="black"/> <!-- 引用黑色材质 -->
            </visual>
            <collision>
                <geometry>
                    <cylinder radius="0.1" length="0.05"/> <!-- 轮子的碰撞体积 -->
                </geometry>
                <origin xyz="0 0 -0.0667" rpy="1.5707963 0 0"/> <!-- 碰撞体积的初始位置和姿态 -->
            </collision>
            <inertial>
                <mass value="1.0"/> <!-- 轮子的质量 -->
                <origin xyz="0 0 -0.0667" rpy="1.5707963 0 0"/> <!-- 质心的位置 -->
                <inertia ixx="0.01" ixy="0" ixz="0" iyy="0.01" iyz="0" izz="0.01"/> <!-- 惯性矩阵 -->
            </inertial>
        </link>

        <joint name="${name}_joint" type="continuous">
            <parent link="base_link"/>
            <child link="${name}"/>
            <origin xyz="${x} ${y} ${z}" rpy="0 0 0"/> <!-- 轮子的位置相对于车身 -->
            <axis xyz="0 1 0"/> <!-- 轮子的旋转轴 -->
        </joint>
    </xacro:macro>

    <!-- 定义相机 -->
    <xacro:macro name="camera" params="name x y z roll pitch yaw">
        <link name="${name}">
            <visual>
                <geometry>
                    <box size="0.05 0.05 0.05"/> <!-- 相机的长宽高 -->
                </geometry>
                <origin xyz="0 0 0" rpy="0 0 0"/> <!-- 相机的初始位置和姿态 -->
                <material name="black"/> <!-- 引用黑色材质 -->
            </visual>
            <collision>
                <geometry>
                    <box size="0.05 0.05 0.05"/> <!-- 相机的碰撞体积 -->
                </geometry>
                <origin xyz="0 0 0" rpy="0 0 0"/> <!-- 碰撞体积的初始位置和姿态 -->
            </collision>
            <inertial>
                <mass value="0.1"/> <!-- 相机的质量 -->
                <origin xyz="0 0 0" rpy="0 0 0"/> <!-- 质心的位置 -->
                <inertia ixx="0.001" ixy="0" ixz="0" iyy="0.001" iyz="0" izz="0.001"/> <!-- 惯性矩阵 -->
            </inertial>
        </link>

        <joint name="${name}_joint" type="fixed">
            <parent link="base_link"/>
            <child link="${name}"/>
            <origin xyz="${x} ${y} ${z}" rpy="${roll} ${pitch} ${yaw}"/> <!-- 相机的位置和姿态相对于车身 -->
        </joint>
    </xacro:macro>

    <!-- 定义激光雷达 -->
    <xacro:macro name="lidar" params="name x y z roll pitch yaw">
        <link name="${name}">
            <visual>
                <geometry>
                    <cylinder radius="0.05" length="0.05"/> <!-- 激光雷达的半径和厚度 -->
                </geometry>
                <origin xyz="0 0 0" rpy="0 0 0"/> <!-- 激光雷达的初始位置和姿态 -->
                <material name="black"/> <!-- 引用黑色材质 -->
            </visual>
            <collision>
                <geometry>
                    <cylinder radius="0.05" length="0.05"/> <!-- 激光雷达的碰撞体积 -->
                </geometry>
                <origin xyz="0 0 0" rpy="0 0 0"/> <!-- 碰撞体积的初始位置和姿态 -->
            </collision>
            <inertial>
                <mass value="0.5"/> <!-- 激光雷达的质量 -->
                <origin xyz="0 0 0" rpy="0 0 0"/> <!-- 质心的位置 -->
                <inertia ixx="0.001" ixy="0" ixz="0" iyy="0.001" iyz="0" izz="0.001"/> <!-- 惯性矩阵 -->
            </inertial>
        </link>

        <joint name="${name}_joint" type="fixed">
            <parent link="base_link"/>
            <child link="${name}"/>
            <origin xyz="${x} ${y} ${z}" rpy="${roll} ${pitch} ${yaw}"/> <!-- 激光雷达的位置和姿态相对于车身 -->
        </joint>
    </xacro:macro>

    <!-- 使用宏定义车轮 -->
    <xacro:wheel name="front_left_wheel" x="0.2" y="0.15" z="-0.0667"/>
    <xacro:wheel name="front_right_wheel" x="0.2" y="-0.15" z="-0.0667"/>
    <xacro:wheel name="rear_left_wheel" x="-0.2" y="0.15" z="-0.0667"/>
    <xacro:wheel name="rear_right_wheel" x="-0.2" y="-0.15" z="-0.0667"/>

    <!-- 使用宏定义相机 -->
    <xacro:camera name="camera" x="0.25" y="0" z="0.1" roll="0" pitch="0" yaw="0"/>

    <!-- 使用宏定义激光雷达 -->
    <xacro:lidar name="lidar" x="0" y="0" z="0.1" roll="0" pitch="0" yaw="0"/>

</robot>