<?xml version="1.0" ?>
<!-- =================================================================================== -->
<!-- |    This document was autogenerated by xacro from xiaoche.xacro                  | -->
<!-- |    EDITING THIS FILE BY HAND IS NOT RECOMMENDED                                 | -->
<!-- =================================================================================== -->
<robot name="bot_xiaoche">
  <!-- 定义颜色 -->
  <material name="red">
    <color rgba="1 0 0 1"/>
    <!-- 红色 用于车身 -->
  </material>
  <material name="black">
    <color rgba="0 0 0 1"/>
    <!-- 黑色 用于车轮 -->
  </material>
  <!-- 定义车身 -->
  <link name="base_link">
    <visual>
      <geometry>
        <box size="0.5 0.3 0.2"/>
        <!-- 车身的长宽高 -->
      </geometry>
      <origin rpy="0 0 0" xyz="0 0 0"/>
      <!-- 车身的初始位置和姿态 -->
      <material name="red"/>
      <!-- 引用红色材质 -->
    </visual>
    <collision>
      <geometry>
        <box size="0.5 0.3 0.2"/>
        <!-- 车身的碰撞体积 -->
      </geometry>
      <origin rpy="0 0 0" xyz="0 0 0"/>
      <!-- 碰撞体积的初始位置和姿态 -->
    </collision>
    <inertial>
      <mass value="50.0"/>
      <!-- 车身的质量 -->
      <origin rpy="0 0 0" xyz="0 0 0"/>
      <!-- 质心的位置 -->
      <inertia ixx="1.0" ixy="0.0" ixz="0.0" iyy="1.0" iyz="0.0" izz="1.0"/>
      <!-- 惯性矩阵 -->
    </inertial>
  </link>
  <link name="front_left_wheel">
    <visual>
      <geometry>
        <cylinder length="0.05" radius="0.1"/>
        <!-- 轮子的半径和厚度 -->
      </geometry>
      <origin rpy="1.5707963 0 0" xyz="0 0 -0.0667"/>
      <!-- 轮子的初始位置和姿态 -->
      <material name="black"/>
      <!-- 引用黑色材质 -->
    </visual>
    <collision>
      <geometry>
        <cylinder length="0.05" radius="0.1"/>
        <!-- 轮子的碰撞体积 -->
      </geometry>
      <origin rpy="1.5707963 0 0" xyz="0 0 -0.0667"/>
      <!-- 碰撞体积的初始位置和姿态 -->
    </collision>
    <inertial>
      <mass value="1.0"/>
      <!-- 轮子的质量 -->
      <origin rpy="1.5707963 0 0" xyz="0 0 -0.0667"/>
      <!-- 质心的位置 -->
      <inertia ixx="0.01" ixy="0" ixz="0" iyy="0.01" iyz="0" izz="0.01"/>
      <!-- 惯性矩阵 -->
    </inertial>
  </link>
  <joint name="front_left_wheel_joint" type="continuous">
    <parent link="base_link"/>
    <child link="front_left_wheel"/>
    <origin rpy="0 0 0" xyz="0.2 0.15 -0.0667"/>
    <!-- 轮子的位置相对于车身 -->
    <axis xyz="0 1 0"/>
    <!-- 轮子的旋转轴 -->
  </joint>
  <link name="front_right_wheel">
    <visual>
      <geometry>
        <cylinder length="0.05" radius="0.1"/>
        <!-- 轮子的半径和厚度 -->
      </geometry>
      <origin rpy="1.5707963 0 0" xyz="0 0 -0.0667"/>
      <!-- 轮子的初始位置和姿态 -->
      <material name="black"/>
      <!-- 引用黑色材质 -->
    </visual>
    <collision>
      <geometry>
        <cylinder length="0.05" radius="0.1"/>
        <!-- 轮子的碰撞体积 -->
      </geometry>
      <origin rpy="1.5707963 0 0" xyz="0 0 -0.0667"/>
      <!-- 碰撞体积的初始位置和姿态 -->
    </collision>
    <inertial>
      <mass value="1.0"/>
      <!-- 轮子的质量 -->
      <origin rpy="1.5707963 0 0" xyz="0 0 -0.0667"/>
      <!-- 质心的位置 -->
      <inertia ixx="0.01" ixy="0" ixz="0" iyy="0.01" iyz="0" izz="0.01"/>
      <!-- 惯性矩阵 -->
    </inertial>
  </link>
  <joint name="front_right_wheel_joint" type="continuous">
    <parent link="base_link"/>
    <child link="front_right_wheel"/>
    <origin rpy="0 0 0" xyz="0.2 -0.15 -0.0667"/>
    <!-- 轮子的位置相对于车身 -->
    <axis xyz="0 1 0"/>
    <!-- 轮子的旋转轴 -->
  </joint>
  <link name="rear_left_wheel">
    <visual>
      <geometry>
        <cylinder length="0.05" radius="0.1"/>
        <!-- 轮子的半径和厚度 -->
      </geometry>
      <origin rpy="1.5707963 0 0" xyz="0 0 -0.0667"/>
      <!-- 轮子的初始位置和姿态 -->
      <material name="black"/>
      <!-- 引用黑色材质 -->
    </visual>
    <collision>
      <geometry>
        <cylinder length="0.05" radius="0.1"/>
        <!-- 轮子的碰撞体积 -->
      </geometry>
      <origin rpy="1.5707963 0 0" xyz="0 0 -0.0667"/>
      <!-- 碰撞体积的初始位置和姿态 -->
    </collision>
    <inertial>
      <mass value="1.0"/>
      <!-- 轮子的质量 -->
      <origin rpy="1.5707963 0 0" xyz="0 0 -0.0667"/>
      <!-- 质心的位置 -->
      <inertia ixx="0.01" ixy="0" ixz="0" iyy="0.01" iyz="0" izz="0.01"/>
      <!-- 惯性矩阵 -->
    </inertial>
  </link>
  <joint name="rear_left_wheel_joint" type="continuous">
    <parent link="base_link"/>
    <child link="rear_left_wheel"/>
    <origin rpy="0 0 0" xyz="-0.2 0.15 -0.0667"/>
    <!-- 轮子的位置相对于车身 -->
    <axis xyz="0 1 0"/>
    <!-- 轮子的旋转轴 -->
  </joint>
  <link name="rear_right_wheel">
    <visual>
      <geometry>
        <cylinder length="0.05" radius="0.1"/>
        <!-- 轮子的半径和厚度 -->
      </geometry>
      <origin rpy="1.5707963 0 0" xyz="0 0 -0.0667"/>
      <!-- 轮子的初始位置和姿态 -->
      <material name="black"/>
      <!-- 引用黑色材质 -->
    </visual>
    <collision>
      <geometry>
        <cylinder length="0.05" radius="0.1"/>
        <!-- 轮子的碰撞体积 -->
      </geometry>
      <origin rpy="1.5707963 0 0" xyz="0 0 -0.0667"/>
      <!-- 碰撞体积的初始位置和姿态 -->
    </collision>
    <inertial>
      <mass value="1.0"/>
      <!-- 轮子的质量 -->
      <origin rpy="1.5707963 0 0" xyz="0 0 -0.0667"/>
      <!-- 质心的位置 -->
      <inertia ixx="0.01" ixy="0" ixz="0" iyy="0.01" iyz="0" izz="0.01"/>
      <!-- 惯性矩阵 -->
    </inertial>
  </link>
  <joint name="rear_right_wheel_joint" type="continuous">
    <parent link="base_link"/>
    <child link="rear_right_wheel"/>
    <origin rpy="0 0 0" xyz="-0.2 -0.15 -0.0667"/>
    <!-- 轮子的位置相对于车身 -->
    <axis xyz="0 1 0"/>
    <!-- 轮子的旋转轴 -->
  </joint>
  <link name="camera">
    <visual>
      <geometry>
        <box size="0.05 0.05 0.05"/>
        <!-- 相机的长宽高 -->
      </geometry>
      <origin rpy="0 0 0" xyz="0 0 0"/>
      <!-- 相机的初始位置和姿态 -->
      <material name="black"/>
      <!-- 引用黑色材质 -->
    </visual>
    <collision>
      <geometry>
        <box size="0.05 0.05 0.05"/>
        <!-- 相机的碰撞体积 -->
      </geometry>
      <origin rpy="0 0 0" xyz="0 0 0"/>
      <!-- 碰撞体积的初始位置和姿态 -->
    </collision>
    <inertial>
      <mass value="0.1"/>
      <!-- 相机的质量 -->
      <origin rpy="0 0 0" xyz="0 0 0"/>
      <!-- 质心的位置 -->
      <inertia ixx="0.001" ixy="0" ixz="0" iyy="0.001" iyz="0" izz="0.001"/>
      <!-- 惯性矩阵 -->
    </inertial>
  </link>
  <joint name="camera_joint" type="fixed">
    <parent link="base_link"/>
    <child link="camera"/>
    <origin rpy="0 0 0" xyz="0.25 0 0.1"/>
    <!-- 相机的位置和姿态相对于车身 -->
  </joint>
  <!-- 添加 Gazebo 插件 -->
  <gazebo reference="camera">
    <sensor name="camera_camera" type="camera">
      <camera>
        <horizontal_fov>1.047</horizontal_fov>
        <image>
          <width>640</width>
          <height>480</height>
          <format>R8G8B8</format>
        </image>
        <clip>
          <near>0.02</near>
          <far>300</far>
        </clip>
      </camera>
      <plugin filename="libgazebo_ros_camera.so" name="camera_controller">
        <ros>
          <namespace>/</namespace>
          <remapping>image_raw:=camera/image_raw</remapping>
        </ros>
        <cameraName>camera</cameraName>
        <frameName>camera_optical_frame</frameName>
        <updateRate>30.0</updateRate>
      </plugin>
    </sensor>
  </gazebo>
  <joint name="lidar_base_mount_joint" type="fixed">
    <origin rpy="0 0 0" xyz="0 0 0.1"/>
    <parent link="base_link"/>
    <child link="lidar_base_link"/>
  </joint>
  <link name="lidar_base_link">
    <inertial>
      <mass value="1.0"/>
      <origin xyz="0 0 0.07212"/>
      <inertia ixx="0.002188947025" ixy="0" ixz="0" iyy="0.002188947025" iyz="0" izz="0.00091036445"/>
    </inertial>
    <visual>
      <geometry>
        <mesh filename="package://velodyne_description/meshes/HDL32E_base.dae"/>
      </geometry>
    </visual>
    <collision>
      <origin rpy="0 0 0" xyz="0 0 0.07212"/>
      <geometry>
        <cylinder length="0.14424" radius="0.04267"/>
      </geometry>
    </collision>
  </link>
  <joint name="lidar_base_scan_joint" type="fixed">
    <origin rpy="0 0 0" xyz="0 0 0.09081"/>
    <parent link="lidar_base_link"/>
    <child link="lidar"/>
  </joint>
  <link name="lidar">
    <inertial>
      <mass value="0.01"/>
      <origin xyz="0 0 0"/>
      <inertia ixx="1e-7" ixy="0" ixz="0" iyy="1e-7" iyz="0" izz="1e-7"/>
    </inertial>
    <visual>
      <origin rpy="0 0 0" xyz="0 0 -0.09081"/>
      <geometry>
        <mesh filename="package://velodyne_description/meshes/HDL32E_scan.dae"/>
      </geometry>
    </visual>
    <collision>
      <geometry>
        <sphere radius="0"/>
      </geometry>
    </collision>
  </link>
  <!-- Gazebo requires the velodyne_gazebo_plugins package -->
  <gazebo reference="lidar">
    <sensor name="lidar-HDL32E" type="ray">
      <pose>0 0 0 0 0 0</pose>
      <visualize>false</visualize>
      <update_rate>10</update_rate>
      <ray>
        <scan>
          <horizontal>
            <samples>2187</samples>
            <resolution>1</resolution>
            <min_angle>-3.141592653589793</min_angle>
            <max_angle>3.141592653589793</max_angle>
          </horizontal>
          <vertical>
            <samples>32</samples>
            <resolution>1</resolution>
            <min_angle>-0.5352924815866609</min_angle>
            <max_angle> 0.18622663118779495</max_angle>
          </vertical>
        </scan>
        <range>
          <min>0.3</min>
          <max>131.0</max>
          <resolution>0.001</resolution>
        </range>
        <noise>
          <type>gaussian</type>
          <mean>0.0</mean>
          <stddev>0.0</stddev>
        </noise>
      </ray>
      <plugin filename="libgazebo_ros_velodyne_laser.so" name="gazebo_ros_laser_controller">
        <ros>
          <namespace>/lidar</namespace>
          <remapping>~/out:=/velodyne_points</remapping>
        </ros>
        <tf_prefix></tf_prefix>
        <frame_name>lidar</frame_name>
        <organize_cloud>False</organize_cloud>
        <min_range>0.9</min_range>
        <max_range>130.0</max_range>
        <gaussian_noise>0.008</gaussian_noise>
      </plugin>
    </sensor>
  </gazebo>
</robot>
